Workbook

Sheet Calculadora
F2: Preencher com as informações | K2: Preencher com as informações DSR | N2: Custo do Funcionário
F3: Salário | I3: 3969.38 | K3: Dias do Mês | L3: 25 | N3: Salário com Horas-Extras | P3: =I16 -> 17969.38
F4: Comissão | K4: Domingos e feriados | L4: 6 | N4: FGTS Mensal (8,0%) | O4: 0.08 | P4: =O4*P3 -> 1437.5504
F5: Hora-Extra 50% | G5: 0.5 | I5: =((((I3+I4)/220)*G5)+(I3+I4)/220)*ROUND((TRUNC(H5)+(MOD(H5,1)*100/60)), 2) -> 0 | N5: Contribuição Previdenciária Patronal | O5: 0.2 | P5: =O5*P3 -> 3593.876
F6: Hora-Extra 100% | G6: 1 | I6: =((((I3+I4)/220)*G6)+(I3+I4)/220)*(TRUNC(H6)+(MOD(H6,1)*100/60)) -> 0 | K6: Dependentes | N6: GILRAT | O6: 0.03 | P6: =P3*O6 -> 539.0814
F7: Gratificação | N7: Outras Entidades | O7: 0.058 | P7: =P3*O7 -> 1042.224
F8: Premiação | I8: 14000 | K8: Teve adiantamento? | L8: Não | N8: FAP | O8: 0.02
F9: DSR Comissão | I9: =(I4/L3)*L4 -> 0 | N9: Total | P9: =SUM(P3:P7) -> 24582.112
F10: DSR | I10: =((I5+I6)/L3)*L4 -> 0 | K10: Dias trabalhados (inlcuir final de semana) | L10: 30
F11: Insalubridade | G11: 0.2 | I11: =IF(J11=TRUE, Cálculo!D27, 0) -> 0 | J11: FALSE
F12: Periculosidade | G12: 0.3 | I12: =IF(J12=TRUE,Cálculo!D32, 0) -> 0 | J12: FALSE
F13: Dias falta | I13: =Cálculo!D37 -> 0 | K13: Informações importantes sobre o uso da planilha: Apenas dois quadros devem serem preenchidos, os demais são calculadas automaticamente e não devem ser alteradas. A primeira parte da planilha apresenta a calculadora, onde você irá colocar os lançamentos para ter a prévia do holerite. No segundo quadro de informações, informe os dias úteis do mês (incluindo os sábados) e, em outro campo, os domingos e feriados As informações devem ser preenchidas nos quadros com diferente das demais. Nas areas que tem quadro para assinalar, clique somente caso tenha aquele lançamento. No terceiro quadro de informações, aparece o custo de cada funcionário além dos valores de folha. Seguindo essas orientações, a planilha funcionará perfeitamente. Em caso de dúvidas, entre em contato conosco.
F14: Horas faltas | I14: =Cálculo!D42 -> 0
F15: Desconto DSR | I15: =Cálculo!D57 -> 0
F16: Total | I16: =SUM(I3:I12)-SUM(I13:I15) -> 17969.38

Sheet Holerite
B2: Prévia de Folha Mensal | G2: Recibo de Pagamento de Salário
B15: Cód | C15: Descrição | G15: Referência | H15: Vencimentos | I15: Descontos
B16: =IF(Calculadora!I3<>"", "1","") -> 1 | C16: =IF(Calculadora!I3<>"", "HORAS NORMAIS","") -> HORAS NORMAIS | G16: =IF(Calculadora!I3<>"", Cálculo!F92, "") -> 9.1666667 | H16: =IF(Calculadora!I3<>"",Calculadora!I3,"") -> 3969.38
B17: =IF(Calculadora!I4<>"", "37", "") | C17: =IF(Calculadora!I4<>"", "COMISSOES", "") | G17: =+IF(Calculadora!I4<>"",Calculadora!I4,"") | H17: =IF(Calculadora!I4<>"",Calculadora!I4,"")
B18: =IF(AND(Calculadora!I5<>"",Calculadora!I5<>0),"5000","") | C18: =IF(AND(Calculadora!I5<>"",Calculadora!I5<>0),"HORAS EXTRA 50%","") | G18: =IF(AND(Calculadora!H5<>"",Calculadora!H5<>0),Calculadora!H5,"") | H18: =IF(AND(Calculadora!I5<>"",Calculadora!I5<>0),Calculadora!I5,"")
B19: =IF(AND(Calculadora!I6<>"",Calculadora!I6<>0),"5001","") | C19: =IF(AND(Calculadora!I6<>"",Calculadora!I6<>0),"HORAS EXTRA 100%","") | G19: =IF(AND(Calculadora!H6<>"",Calculadora!H6<>0),Calculadora!H6,"") | H19: =IF(AND(Calculadora!I6<>"",Calculadora!I6<>0),Calculadora!I6,"")
B20: =IF(Calculadora!I7<>"", "20", "") | C20: =IF(Calculadora!I7<>"", "GRATIFICACOES", "") | G20: =IF(AND(Calculadora!I7<>"",Calculadora!I7<>0),Calculadora!I7,"") | H20: =IF(AND(Calculadora!I7<>"",Calculadora!I7<>0),Calculadora!I7,"")
B21: =IF(Calculadora!I8<>"", "5080", "") -> 5080 | C21: =IF(Calculadora!I8<>"", "PREMIO", "") -> PREMIO | H21: =IF(AND(Calculadora!I8<>"",Calculadora!I8<>0),Calculadora!I8,"") -> 14000
B22: =IF(AND(Calculadora!I10<>"",Calculadora!I10<>0),"250","") | C22: =IF(AND(Calculadora!I10<>"",Calculadora!I10<>0),"REFLEXO EXTRA DSR","") | H22: =IF(AND(Calculadora!I10<>"",Calculadora!I10<>0),Calculadora!I10,"")
B23: =IF(AND(Calculadora!I9<>"",Calculadora!I9<>0),"853","") | C23: =IF(AND(Calculadora!I9<>"",Calculadora!I9<>0),"REFLEXO COMISSOES DSR","") | H23: =IF(AND(Calculadora!I9<>"",Calculadora!I9<>0),Calculadora!I9,"")
B24: =IF(AND(Calculadora!I11<>"",Calculadora!I11<>0),IF(Calculadora!G11=10%, "15", IF(Calculadora!G11=20%, "16", IF(Calculadora!G11=40%, "17", ""))),"") | C24: =IF(AND(Calculadora!I11<>"",Calculadora!I11<>0),IF(Calculadora!G11=10%, "INSALUBRIDADE 10%", IF(Calculadora!G11=20%, "INSALUBRIDADE 20%", IF(Calculadora!G11=40%, "1INSALUBRIDADE 40%", ""))),"") | G24: =IF(AND(Calculadora!H11<>"",Calculadora!H11<>0),Calculadora!G11,"") | H24: =IF(AND(Calculadora!I11<>"",Calculadora!I11<>0),Calculadora!I11,"")
B25: =IF(AND(Calculadora!I12<>"",Calculadora!I12<>0),"217","") | C25: =IF(AND(Calculadora!I12<>"",Calculadora!I12<>0),"PERICULOSIDADE","") | G25: =IF(AND(Calculadora!H12<>"",Calculadora!H12<>0),Calculadora!G12,"") | H25: =IF(AND(Calculadora!I12<>"",Calculadora!I12<>0),Calculadora!I12,"")
B26: =IF(AND(Calculadora!I13<>"",Calculadora!I13<>0),"8792","") | C26: =IF(AND(Calculadora!I13<>"",Calculadora!I13<>0),"DIAS FALTAS","") | G26: =IF(AND(Calculadora!G13<>"",Calculadora!G13<>0),Calculadora!G13,"") | I26: =IF(AND(Calculadora!I13<>"",Calculadora!I13<>0),Calculadora!I13,"")
B27: =IF(AND(Calculadora!I14<>"",Calculadora!I14<>0),"8069","") | C27: =IF(AND(Calculadora!I14<>"",Calculadora!I14<>0),"HORAS FALTAS","") | G27: =IF(AND(Calculadora!G14<>"",Calculadora!G14<>0),Calculadora!G14,"") | H27: =IF(AND(Calculadora!O17<>"",Calculadora!O17<>0),Calculadora!I14,"") | I27: =IF(AND(Calculadora!I14<>"",Calculadora!I14<>0),Calculadora!I14,"")
B28: =IF(AND(Calculadora!I15<>"",Calculadora!I15<>0),"8794","") | C28: =IF(AND(Calculadora!I15<>"",Calculadora!I15<>0),"DESCONTO DE DSR","") | G28: =IF(AND(Calculadora!G15<>"",Calculadora!G15<>0),Calculadora!G15,"") | I28: =IF(AND(Calculadora!I15<>"",Calculadora!I15<>0),Calculadora!I15,"")
B29: =IF(AND('NÃO MEXER'!C10<>"",'NÃO MEXER'!C10<>0),"998","") -> 998 | C29: =IF(AND('NÃO MEXER'!C10<>"",'NÃO MEXER'!C10<>0),"INSS","") -> INSS | I29: =IF(AND('NÃO MEXER'!C10<>"",'NÃO MEXER'!C10<>0),'NÃO MEXER'!C10,"") -> 364.91
B30: =IF(AND('NÃO MEXER'!C11<>"",'NÃO MEXER'!C11<>0),"999","") -> 999 | C30: =IF(AND('NÃO MEXER'!C11<>"",'NÃO MEXER'!C11<>0),"IMPOSTO DE RENDA","") -> IMPOSTO DE RENDA | I30: =IF(AND('NÃO MEXER'!C11<>"",'NÃO MEXER'!C11<>0),'NÃO MEXER'!C11,"") -> 3865.8695
B31: =IF(AND(Calculadora!L8<>"Não",Calculadora!L8<>0),"981","") | C31: =IF(AND(Calculadora!L8<>"Não",Calculadora!L8<>0),"ADIANTAMENTO SALARIAL","") | I31: =IF(AND(Calculadora!L8<>"Não",Calculadora!L8<>0),Cálculo!E87,"")
H33: Total de vencimentos | I33: Total de descontos
H34: =SUM(H16:H32) -> 17969.38 | I34: =SUM(I16:I32) -> 4230.7795
I36: =H34-I34 -> 13738.601

Sheet Tabelas
H1: Tabela Progressiva IRRF
A2: TABELA VIGENTE INSS | E2: FATOR DE CÁLCULO | H2: Base de Cálculo (R$) | J2: Alíquota (%) | K2: Parcela a Deduzir do IR (R$)
A3: Tabela de contribuição dos segurados empregado, empregado doméstico e trabalhador avulso, para pagamento de remuneração a partir de 1º de Janeiro de 2013 | H3: 0 | I3: 2428.8 | J3: 0 | K3: 0
A4: Salário-de-contribuição (R$) | B4: Alíquota para fins de recolhimento ao INSS (%) | E4: =Calculadora!I16-Calculadora!I8 -> 3969.38 | F4: CÁLCULO INSS | H4: 2428.81 | I4: 2826.65 | J4: 0.075 | K4: 182.16
A5: 0 | B5: 1621 | C5: 0.075 | D5: =B5-A5 -> 1621 | E5: =IF(E4>=B5,B5,E4) -> 1621 | F5: =TRUNC(E5*C5,2) -> 121.57 | H5: 2826.66 | I5: 3751.05 | J5: 0.15 | K5: 394.16
A6: 1621.01 | B6: 2902.84 | C6: 0.09 | D6: =B6-A6 -> 1281.83 | E6: =IF(AND(E4>E5,E4<B6),E4-E5,IF(E4>B6,B6-A6,0)) -> 1281.83 | F6: =TRUNC(E6*C6,2) -> 115.36 | H6: 3751.06 | I6: 4664.68 | J6: 0.225 | K6: 675.49
A7: 2902.85 | B7: 4354.27 | C7: 0.12 | D7: =B7-A7 -> 1451.42 | E7: =IF(E4>B7,B7-A7,IF(E4<A7,0,E4-A7)) -> 1066.53 | F7: =TRUNC(E7*C7,2) -> 127.98 | H7: 4664.69 | I7: 999999 | J7: 0.275 | K7: 908.73
A8: 4354.28 | B8: 8475.55 | C8: 0.14 | D8: =B8-A8 -> 4121.27 | E8: =IF(E4>B8,B8-A8,IF(E4<A8,0,E4-A8)) -> 0 | F8: =TRUNC(E8*C8,2) -> 0
B9: =B7-A7 -> 1451.42 | E9: =SUM(E5:E8) -> 3969.36 | H9: Dedução por dependente: R$ 179,71 (cento e setenta e um reais e noventa e sete centavos). | K9: 189.59
E13: regra estouro | F13: =IF(E4>B8,D8,"0,00") -> 0,00 | T13: v
E14: regra dentro | F14: =IF(AND(E4>B7,E4<B8),E4-B7,0) -> 0

Sheet Cálculo
B2: DEDUÇÃO LEGAL
B3: Quantidade de Dependentes | C3: ='NÃO MEXER'!C9 -> 0 | H3: DEDUÇÇÃO SIMPLIFICADA
B4: Dedução por dependente | C4: 189.59 | H4: Dedução 25% s/ 1ª faixa | I4: 607.2
B5: Valor da Base | C5: =B22-(C4*C3) -> 17604.47 | H5: Valor da base | I5: =D62-Cálculo!I4 -> 17362.18
B6: Inicial | C6: Final | D6: Alíquota | E6: Dedução | F6: Legal | G6: Simplificado
B7: 0 | C7: 2428.8 | D7: 0 | E7: 0 | F7: 0 | G7: 0
B8: 2428.81 | C8: 2826.65 | D8: 0.075 | E8: 182.16 | F8: =IF(AND($C$5>B8,$C$5<C8),($C$5*D8)-E8,0) -> 0 | G8: =IF(AND($I$5>B8,$I$5<C8),($I$5*D8)-E8,0) -> 0
B9: 2826.66 | C9: 3751.05 | D9: 0.15 | E9: 394.16 | F9: =IF(AND($C$5>B9,$C$5<C9),($C$5*D9)-E9,0) -> 0 | G9: =IF(AND($I$5>B9,$I$5<C9),($I$5*D9)-E9,0) -> 0
B10: 3751.06 | C10: 4664.68 | D10: 0.225 | E10: 675.49 | F10: =IF(AND($C$5>B10,$C$5<C10),($C$5*D10)-E10,0) -> 0 | G10: =IF(AND($I$5>B10,$I$5<C10),($I$5*D10)-E10,0) -> 0
B11: 4664.69 | C11: 99999.99 | D11: 0.275 | E11: 908.73 | F11: =IF(AND($C$5>B11,$C$5<C11),($C$5*D11)-E11,0) -> 3932.4993 | G11: =IF(AND($I$5>B11,$I$5<C11),($I$5*D11)-E11,0) -> 3865.8695
B12: Desconto Legal: | C12: =SUM(F7:F11) -> 3932.4993
B13: Desconto Simplificado: | C13: =SUM(G7:G11) -> 3865.8695
B15: Melhor opção para o empregado: | C15: =IF(C13>C12,"LEGAL","SIMPLIFICADO") -> SIMPLIFICADO | D15: =IF(C15="LEGAL",C12,C13) -> 3865.8695
A19: INSS DESCONTADO | B19: ='NÃO MEXER'!C10 -> 364.91
A20: DEPENDENTES IR | B20: ='[1]Salário Líquido 2025'!C24*[1]Tabelas!K24 -> 0
B21: Liquido | C21: Alíquota | D21: Vlr Imposto | E21: Vlr a Deduzir | F21: IR a Pagar
A22: Base IR | B22: =D62-Cálculo!B19 -> 17604.47 | C22: =VLOOKUP(B22,Tabelas!H3:J7,3) -> 0.275 | D22: =B22*C22 -> 4841.2293 | E22: =IF(VLOOKUP(C22,Tabelas!J4:K7,2)>0,VLOOKUP(C22,Tabelas!J4:K7,2),0) -> 908.73 | F22: =D22-E22 -> 3932.4993
A26: Insalubridade | B26: Porcentagem | C26: Salario mínimo
B27: =Calculadora!G11 -> 0.2 | C27: 1621 | D27: =C27*B27 -> 324.2
A31: Periculosidade | B31: Porcentagem | C31: Salario Funcionário
B32: =Calculadora!G12 -> 0.3 | C32: =SUM(Calculadora!I3:I4) -> 3969.38 | D32: =C32*B32 -> 1190.814
A36: Dias falta | B36: Dias Falta | C36: Salario Funcionário
B37: =Calculadora!H13 -> 0 | C37: =SUM(Calculadora!I3:I4) -> 3969.38 | D37: =(C37/30)*B37 -> 0
A41: Horas falta | B41: Horas falta | C41: Salario Funcionário
B42: =Calculadora!H14 -> 0 | C42: =SUM(Calculadora!I3:I4) -> 3969.38 | D42: =(C42/220) * ROUND( (TRUNC(B42) + (B42-TRUNC(B42)) * 100/60), 2) -> 0
A46: Adicional noturno | B46: Porcentagem | C46: Salario Funcionário | D46: Horas mensal | E46: Adicional noturno
B47: =Calculadora!#REF! -> #REF! | C47: =SUM(Calculadora!I3:I4) -> 3969.38 | D47: 220 | E47: =(C47/D47)*B47 -> #REF! | F47: =(TRUNC(Calculadora!#REF!)+(MOD(Calculadora!#REF!,1)*100/60))*Cálculo!E47 -> #REF!
A51: Hora extra noturna | B51: Porcentagem | C51: Salario Funcionário | D51: Horas mensal | E51: Valor hora normal | F51: Adicional noturno | G51: Hora noturna | H51: Valor adicional de horas extra | I51: Uma hora extra noturna | J51: Valor final
B52: =Calculadora!#REF! -> #REF! | C52: =SUM(Calculadora!I3:I4) -> 3969.38 | D52: 220 | E52: =C52/D52 -> 18.042636 | F52: =E52*B47 -> #REF! | G52: =SUM(E52,F52) -> #REF! | H52: =G52*B52 -> #REF! | I52: =G52+H52 -> #REF! | J52: =I52*(TRUNC(Calculadora!#REF!)+(MOD(Calculadora!#REF!,1)*100/60)) -> #REF!
A56: Desconto de DSR | B56: Dias Falta | C56: Salario Funcionário | D56: Valor desconto
B57: =Calculadora!H15 -> 0 | C57: =SUM(Calculadora!I3:I4) -> 3969.38 | D57: =(C57/30)*B57 -> 0
A61: Base de IR | B61: Soma | C61: Subtração | D61: Total
B62: =SUM(Calculadora!I3,Calculadora!I4,Calculadora!I5,Calculadora!I6,Calculadora!I7:I12) -> 17969.38 | C62: =SUM(Calculadora!I13,Calculadora!I14) -> 0 | D62: =B62-C62 -> 17969.38
A66: Finalização IRRF | B66: Claculo
B67: =IF((B22 + B19 + (C3 * C4)) <= 5000, 0, D15) -> 3865.8695
A71: calculo complexo | B71: Salário Bruto | C71: Calculo
B72: =SUM(Calculadora!I3:I12) -> 17969.38 | C72: =IF(AND(B72>5000, B72<=7350),978.62-(0.133145*B72),0) -> 0
A76: Calculo final | B76: Calculo
B77: =D15-C72 -> 3865.8695
A81: Valor a enviar IR
...

Sheet NÃO MEXER
B2: Salário Líquido
B4: (+) Salário Contribuição (Somar tudo) | C4: =Calculadora!I16 -> 17969.38
B5: -- | C5: 0
B7: Base total | C7: =C4 -> 17969.38
B9: Dependentes | C9: =Calculadora!L6 -> 0
B10: (-) INSS | C10: =SUM(Tabelas!F5:F8) -> 364.91
B11: (-) IRRF | C11: =Cálculo!B82 -> 3865.8695
B14: Líquido que o funcionário recebe | C14: =C7-C10-C11 -> 13738.601
